Workbook

Sheet Program Overview
A1: PYTHON FOR DATA SCIENCE & MACHINE LEARNING
A2: Corporate Training Program | 40 Hours (2,400 Minutes) | 10 Days x 4 Hours
A4: Parameter | B4: Details
A5: Program Name | B5: Python for Data Science & Machine Learning
A6: Total Duration | B6: 40 Hours (2,400 minutes)
A7: Recommended Schedule | B7: 10 sessions x 4 hours (2 hours instruction + 2 hours guided hands-on per session)
A8: Delivery Mode | B8: Instructor-led (online or classroom) with live coding and per-participant lab work
A9: Target Audience | B9: Software Developers, SDETs, QA Engineers, Technology Leads, Architects, Application Support Engineers
A10: Audience Experience | B10: Mostly beginners in Python and Machine Learning; some participants have basic Python; a few have automation-scripting exposure
A11: Prerequisites | B11: Programming logic in any language; basic mathematics; laptop with admin rights for installations; no prior Python or ML experience assumed
A12: Theory : Practical Ratio | B12: Approximately 40% concept, 60% hands-on implementation
A13: Total Modules | B13: 10
A14: Total Topics | B14: =COUNTA('Course ToC'!A4:A200)-1
A15: Batch Size Recommended | B15: 15-20 participants (maximum 25 for effective lab support)
A17: LEARNING OBJECTIVES
A18: Objective 1 | B18: Understand and write the Python required for data science work, from core syntax to OOP and engineering practices
A19: Objective 2 | B19: Perform numerical computing and data analysis using NumPy and Pandas at production scale
A20: Objective 3 | B20: Clean, wrangle and engineer features from messy, real-world enterprise data
A21: Objective 4 | B21: Create analytical and presentation-grade visualisations and run a disciplined EDA
A22: Objective 5 | B22: Explain machine learning concepts, learning paradigms, evaluation metrics and the bias-variance trade-off
A23: Objective 6 | B23: Build, tune and evaluate regression, classification, ensemble and clustering models
A24: Objective 7 | B24: Package models into leakage-free pipelines and expose them through a scoring service
A25: Objective 8 | B25: Deliver one complete, enterprise-style end-to-end machine learning project
A26: Objective 9 | B26: Apply industry best practices covering reproducibility, testing, explainability and responsible AI
A27: Objective 10 | B27: Be confident and equipped to continue advanced learning independently
A29: ASSESSMENT APPROACH
A30: Daily | B30: Hands-on lab completion checked against the deliverable listed for each topic
A31: Mid-program | B31: Module 1-6 quiz plus an EDA report evaluation
A32: Final | B32: Capstone project submission, code walkthrough and presentation
A33: Certification Criteria | B33: Minimum 80% attendance, all lab deliverables submitted, and capstone project presented
A35: Prepared By | B35: ANALYTICSWITHANAND - Corporate Training & Upskilling
A36: Document Version | B36: 1.0 - 40 Hour Edition (scaled from the 4-hour learning-needs input)

Sheet Course ToC
A1: DETAILED TABLE OF CONTENTS - PYTHON FOR DATA SCIENCE & MACHINE LEARNING
A2: 40 Hours | 2,400 Minutes | 10 Modules | Theory + Hands-on | One row per topic
A4: Module Number | B4: Module Name | C4: Detailed Topics Covered | D4: Theory Concepts | E4: Hands-on Practical Exercise | F4: Real-world Example / Industry Use Case | G4: Expected Learning Outcome | H4: Duration (Minutes) | I4: Difficulty Level | J4: Prerequisites | K4: Tools/Libraries Used | L4: Deliverables
A5: Module 1 | B5: Python Foundations for Data Science | C5: 1.1 Python Ecosystem, Environment Setup & Jupyter | D5: Why Python for data science; interpreter vs compiler; CPython execution model; Anaconda vs venv vs pip; Jupyter Notebook / JupyterLab / VS Code; kernels, cells, magic commands; notebook vs script discipline | E5: Install Anaconda, create a dedicated conda environment, launch JupyterLab, run and export a first notebook, verify library versions | F5: Standardising a single reproducible analytics environment across a distributed dev/QA team so notebooks run identically on every machine | G5: Set up a working, reproducible Python data-science environment and navigate Jupyter confidently | H5: 30 | I5: Beginner | J5: Basic computer literacy | K5: Anaconda, Python 3.11, JupyterLab, VS Code | L5: Working environment + verified setup notebook
A6: Module 1 | B6: Python Foundations for Data Science | C6: 1.2 Variables, Data Types & the Type System | D6: Dynamic typing; int, float, str, bool, complex, None; mutable vs immutable objects; object references and identity; type casting and coercion; memory model basics | E6: Write a type-explorer script that prints type, id and mutability for 10 objects; demonstrate the mutable-default-argument trap | F6: Parsing heterogeneous fields (IDs, timestamps, amounts) coming from application logs where every value arrives as a string | G6: Choose the correct data type for a field and explain mutability side effects | H6: 25 | I6: Beginner | J6: Module 1.1 | K6: Python core, Jupyter | L6: types_and_variables.ipynb
A7: Module 1 | B7: Python Foundations for Data Science | C7: 1.3 Operators & Expressions | D7: Arithmetic, comparison, logical, assignment, bitwise, membership and identity operators; operator precedence and associativity; short-circuit evaluation; == vs is | E7: Build a test-metrics calculator computing pass %, defect density and escape rate from raw counts | F7: Automated computation of QA quality KPIs from a nightly regression run | G7: Write correct expressions and avoid precedence and identity-comparison bugs | H7: 20 | I7: Beginner | J7: Module 1.2 | K7: Python core | L7: qa_metrics_calculator.py
A8: Module 1 | B8: Python Foundations for Data Science | C8: 1.4 Input / Output & String Handling | D8: input() and print(); f-strings and format specifiers; string methods (split, strip, replace, join, find); slicing; escape characters; introduction to regular expressions with re | E8: Parse a raw application log line into timestamp, severity, module and message fields using string methods and one regex | F8: Log-file triage in application support: turning unstructured log text into structured, searchable fields | G8: Manipulate and extract information from text data programmatically | H8: 25 | I8: Beginner | J8: Module 1.2 | K8: Python core, re | L8: log_parser.py
A9: Module 1 | B9: Python Foundations for Data Science | C9: 1.5 Conditional Statements & Control Flow | D9: if / elif / else; nested conditions; ternary expression; truthiness of Python objects; match-case (structural pattern matching); guard clauses and readability | E9: Implement a defect-severity classifier that maps impact and frequency inputs to P1-P4 priority | F9: Auto-triage rules that assign incident priority before a ticket reaches an engineer | G9: Express business rules as clean, readable conditional logic | H9: 20 | I9: Beginner | J9: Module 1.3 | K9: Python core | L9: severity_classifier.py
A10: Module 1 | B10: Python Foundations for Data Science | C10: 1.6 Loops & Iteration | D10: for and while loops; range, enumerate, zip; break, continue and the loop-else clause; nested loops; iteration over files and collections; loop performance considerations | E10: Iterate over a CSV of test runs, aggregate durations per suite, and flag runs exceeding an SLA threshold | F10: Batch processing of daily automation results without any external library | G10: Automate repetitive processing over collections and files | H10: 25 | I10: Beginner | J10: Module 1.5 | K10: Python core, csv | L10: batch_test_processor.py
A11: Module 1 | B11: Python Foundations for Data Science | C11: 1.7 Core Data Structures - List, Tuple, Set, Dictionary | D11: List vs tuple vs set vs dict; ordering, mutability and hashability; indexing and slicing; nested structures; dict and set methods; set algebra; time complexity of common operations | E11: Model a defect tracker as a dict of lists, deduplicate incident IDs with sets, and build a nested JSON-like structure | F11: Consolidating duplicate incident tickets raised by multiple monitoring tools into one canonical record | G11: Select the right data structure for a problem based on access pattern and complexity | H11: 35 | I11: Beginner | J11: Module 1.6 | K11: Python core | L11: data_structures_workbook.ipynb
A12: Module 1 | B12: Python Foundations for Data Science | C12: 1.8 Functions, Scope & Type Hints | D12: def and return; positional, keyword and default arguments; *args and **kwargs; LEGB scope rules; pure vs impure functions; docstrings; type hints and the typing module; modular design | E12: Build a small reusable data-cleaning function library (trim, standardise case, coerce numeric, validate email) with docstrings and type hints | F12: Creating a shared utility library that every analyst on the team imports instead of copy-pasting logic | G12: Write reusable, documented, testable functions instead of monolithic scripts | H12: 30 | I12: Beginner | J12: Module 1.7 | K12: Python core, typing | L12: cleaning_utils.py
A13: Module 1 | B13: Python Foundations for Data Science | C13: 1.9 Lambda, map, filter & reduce | D13: Anonymous functions; functions as first-class objects; map / filter / reduce; sorted with key functions; functional vs imperative style; when lambda hurts readability | E13: Transform a list of test durations: convert units with map, filter outliers, and rank suites using sorted(key=...) | F13: Compact in-line transformations inside data pipelines and Pandas apply calls | G13: Apply functional constructs where they simplify code and recognise where they do not | H13: 20 | I13: Beginner | J13: Module 1.8 | K13: Python core, functools | L13: functional_python.ipynb
A14: Module 1 | B14: Python Foundations for Data Science | C14: 1.10 List, Dict & Set Comprehensions + Generator Expressions | D14: Comprehension syntax; conditional and nested comprehensions; dict and set comprehensions; generator expressions and lazy evaluation; memory and speed trade-offs; readability limits | E14: Rewrite three loop-based transformations as comprehensions and benchmark memory and runtime against a generator expression | F14: Memory-efficient transformation of multi-million-row extracts on a constrained machine | G14: Write concise, Pythonic transformations and reason about their memory footprint | H14: 25 | I14: Intermediate | J14: Module 1.9 | K14: Python core, sys, timeit | L14: comprehensions_benchmark.ipynb
A15: Module 1 | B15: Python Foundations for Data Science | C15: 1.11 Module 1 Consolidation, Quiz & Q&A | D15: Recap of the Python foundation stack; common beginner pitfalls; coding-standard checklist; guided doubt clearing | E15: Timed 15-question quiz plus a mini coding challenge combining functions, dictionaries and comprehensions | F15: Skills baseline check used by L&D to confirm readiness before the data-analysis track | G15: Confirm command of core Python before moving to the data-analysis libraries | H15: 15 | I15: Beginner | J15: Modules 1.1-1.10 | K15: Python core | L15: Quiz score sheet + solution notebook
A16: Module 2 | B16: Advanced Python & Engineering Practices | C16: 2.1 Exception Handling & Logging | D16: try / except / else / finally; exception hierarchy; catching specific vs bare exceptions; raise and re-raise; custom exception classes; context of failure; the logging module, levels and handlers | E16: Build a resilient CSV loader with targeted exception handling, a custom DataQualityError, retry logic and structured logging to file | F16: A nightly ingestion job that must fail loudly with a diagnosable log rather than silently producing partial data | G16: Write fault-tolerant code that fails predictably and leaves a usable audit trail | H16: 30 | I16: Intermediate | J16: Module 1 | K16: Python core, logging | L16: resilient_loader.py + run log
... A82: Module 10 | B82: End-to-End Capstone Project | C82: 10.9 Project Presentation, Code Walkthrough & Learning Roadmap | D82: Structuring a technical and an executive narrative; presenting results without jargon; defending methodology choices; code walkthrough and review; deployment and monitoring next steps; a personal roadmap for continued learning | E82: Present the capstone to the group, walk through the code, defend three design decisions, and draft an individual 90-day learning plan | F82: The final project readout to sponsors that decides whether the work moves to production | G82: Present and defend an end-to-end ML project and plan independent advanced learning | H82: 20 | I82: Advanced | J82: Modules 10.1-10.8 | K82: Jupyter, PowerPoint | L82: Capstone deck + final project repository
G83: TOTAL PROGRAM DURATION | H83: =SUM(H5:H82) | I83: =ROUND(H83/60,1)&" hours" | J83: =COUNTA(C5:C82)&" topics"

Sheet Duration Summary
A1: MODULE-WISE DURATION SUMMARY
A2: Total must equal 2,400 minutes (40 hours)
A4: Module | B4: Module Name | C4: Topics | D4: Minutes | E4: Hours | F4: % of Program | G4: Suggested Day
A5: Module 1 | B5: Python Foundations for Data Science | C5: =COUNTIF('Course ToC'!$A$5:$A$82,A5) | D5: =SUMIF('Course ToC'!$A$5:$A$82,A5,'Course ToC'!$H$5:$H$82) | E5: =ROUND(D5/60,2) | F5: =D5/$D$15 | G5: Day 1
A6: Module 2 | B6: Advanced Python & Engineering Practices | C6: =COUNTIF('Course ToC'!$A$5:$A$82,A6) | D6: =SUMIF('Course ToC'!$A$5:$A$82,A6,'Course ToC'!$H$5:$H$82) | E6: =ROUND(D6/60,2) | F6: =D6/$D$15 | G6: Day 2
A7: Module 3 | B7: NumPy for Numerical Computing | C7: =COUNTIF('Course ToC'!$A$5:$A$82,A7) | D7: =SUMIF('Course ToC'!$A$5:$A$82,A7,'Course ToC'!$H$5:$H$82) | E7: =ROUND(D7/60,2) | F7: =D7/$D$15 | G7: Day 3
A8: Module 4 | B8: Pandas for Data Analysis | C8: =COUNTIF('Course ToC'!$A$5:$A$82,A8) | D8: =SUMIF('Course ToC'!$A$5:$A$82,A8,'Course ToC'!$H$5:$H$82) | E8: =ROUND(D8/60,2) | F8: =D8/$D$15 | G8: Day 3-4
A9: Module 5 | B9: Data Cleaning, Wrangling & Feature Engineering | C9: =COUNTIF('Course ToC'!$A$5:$A$82,A9) | D9: =SUMIF('Course ToC'!$A$5:$A$82,A9,'Course ToC'!$H$5:$H$82) | E9: =ROUND(D9/60,2) | F9: =D9/$D$15 | G9: Day 5
A10: Module 6 | B10: Data Visualisation & Exploratory Data Analysis | C10: =COUNTIF('Course ToC'!$A$5:$A$82,A10) | D10: =SUMIF('Course ToC'!$A$5:$A$82,A10,'Course ToC'!$H$5:$H$82) | E10: =ROUND(D10/60,2) | F10: =D10/$D$15 | G10: Day 6
A11: Module 7 | B11: Statistics & Machine Learning Theory | C11: =COUNTIF('Course ToC'!$A$5:$A$82,A11) | D11: =SUMIF('Course ToC'!$A$5:$A$82,A11,'Course ToC'!$H$5:$H$82) | E11: =ROUND(D11/60,2) | F11: =D11/$D$15 | G11: Day 7
A12: Module 8 | B12: Machine Learning - Practical Implementation | C12: =COUNTIF('Course ToC'!$A$5:$A$82,A12) | D12: =SUMIF('Course ToC'!$A$5:$A$82,A12,'Course ToC'!$H$5:$H$82) | E12: =ROUND(D12/60,2) | F12: =D12/$D$15 | G12: Day 8
A13: Module 9 | B13: Unsupervised Learning, Tuning, Pipelines & Deployment | C13: =COUNTIF('Course ToC'!$A$5:$A$82,A13) | D13: =SUMIF('Course ToC'!$A$5:$A$82,A13,'Course ToC'!$H$5:$H$82) | E13: =ROUND(D13/60,2) | F13: =D13/$D$15 | G13: Day 9
A14: Module 10 | B14: End-to-End Capstone Project | C14: =COUNTIF('Course ToC'!$A$5:$A$82,A14) | D14: =SUMIF('Course ToC'!$A$5:$A$82,A14,'Course ToC'!$H$5:$H$82) | E14: =ROUND(D14/60,2) | F14: =D14/$D$15 | G14: Day 10
B15: TOTAL | C15: =SUM(C5:C14) | D15: =SUM(D5:D14) | E15: =ROUND(D15/60,2) | F15: =SUM(F5:F14) | G15: 10 Days x 4 Hours
B17: Note: Minutes and topic counts are formula-linked to the 'Course ToC' sheet and update automatically if any topic duration is edited.

Sheet Training Roadmap
A1: TRAINING ROADMAP - 10 DAYS x 4 HOURS
A2: Day-wise delivery plan, focus areas and daily outcomes
A4: Day | B4: Modules Covered | C4: Focus Area | D4: Key Topics of the Day | E4: Day-End Outcome | F4: Duration (Min)
A5: Day 1 | B5: Module 1 | C5: Python Core Foundations | D5: Environment setup; variables and data types; operators; I/O and strings; conditionals; loops; data structures; functions; lambda; comprehensions; quiz | E5: Participants can write clean, working Python programs using functions, collections and comprehensions | F5: 270
A6: Day 2 | B6: Module 2 | C6: Advanced Python & Engineering Practices | D6: Exception handling and logging; file handling; OOP (classes, inheritance, polymorphism, abstraction); modules and packaging; generators and decorators; PEP 8, debugging and pytest | E6: Participants can structure Python as a tested, packaged, production-quality codebase | F6: 210
A7: Day 3 | B7: Module 3 + Module 4 (part) | C7: NumPy & Pandas Foundations | D7: ndarray, indexing, reshaping, broadcasting, vectorisation, linear algebra; Series and DataFrame; reading CSV, Excel, JSON and SQL | E7: Participants can perform vectorised numerical computing and ingest any enterprise data format | F7: 220
A8: Day 4 | B8: Module 4 (remaining) | C8: Pandas Data Analysis | D8: loc/iloc/query selection; sorting and transformations; GroupBy and aggregations; merge, join and concat; pivot, melt and reshaping; time series basics | E8: Participants can analyse, aggregate, join and reshape multi-source data confidently | F8: 200
A9: Day 5 | B9: Module 5 | C9: Data Cleaning & Feature Engineering | D9: Data profiling and quality scorecard; missing values; duplicates and outliers; encoding; scaling and transformation; feature engineering and selection; data leakage | E9: Participants can turn a messy raw dataset into a clean, leakage-free modelling dataset | F9: 210
A10: Day 6 | B10: Module 6 | C10: Visualisation & EDA | D10: Matplotlib fundamentals; distribution, relationship and categorical plots; correlation heatmaps; Seaborn facets and theming; structured EDA and storytelling | E10: Participants can run a full EDA and present quantified insights to a business audience | F10: 210
A11: Day 7 | B11: Module 7 | C11: Statistics & Machine Learning Theory | D11: Statistics for ML; AI vs ML vs DL; types of ML; ML lifecycle and problem framing; train/test split and cross validation; bias-variance, overfitting and underfitting; regression and classification metrics | E11: Participants can frame an ML problem correctly and choose an appropriate validation strategy and metric | F11: 240
A12: Day 8 | B12: Module 8 | C12: Machine Learning Implementation | D12: scikit-learn API and baselines; linear and regularised regression; logistic regression; decision trees; random forest; boosting and XGBoost; KNN, Naive Bayes and SVM; model comparison | E12: Participants can build, evaluate and compare a full portfolio of supervised models | F12: 330
A13: Day 9 | B13: Module 9 | C13: Unsupervised Learning, Tuning & Deployment | D13: K-Means, hierarchical clustering and DBSCAN; PCA; hyperparameter tuning; Pipelines and ColumnTransformer; model persistence and a FastAPI scoring endpoint; SHAP and responsible AI | E13: Participants can tune, package and serve a model and explain its behaviour | F13: 240
A14: Day 10 | B14: Module 10 | C14: End-to-End Capstone Project | D14: Problem framing; data ingestion; cleaning; EDA; feature engineering; model building; tuning and selection; business insights; presentation and code walkthrough | E14: Participants deliver a complete, enterprise-style ML project and present it | F14: 270
E15: TOTAL | F15: =SUM(F5:F14)
A17: Suggested daily structure: 10:00-11:30 concept and live coding | 11:30-11:45 break | 11:45-13:15 guided hands-on lab | 13:15-14:00 lab review, doubt clearing and deliverable submission.

Sheet Required Software & Setup
A1: REQUIRED SOFTWARE & INSTALLATION GUIDE
A2: To be completed and verified by every participant before Day 1
A4: S.No | B4: Software / Library | C4: Version | D4: Mandatory | E4: Installation Command / Steps | F4: Purpose | G4: Verification
A5: 1 | B5: Anaconda Distribution | C5: 2024.02+ | D5: Yes | E5: Download from anaconda.com/download and run the installer; select 'Add to PATH' on Windows | F5: Bundles Python, Jupyter and the core data-science stack in one install | G5: conda --version
A6: 2 | B6: Python | C6: 3.10 - 3.11 | D6: Yes | E6: Included with Anaconda; otherwise download from python.org | F6: Core programming language for the entire program | G6: python --version
A7: 3 | B7: JupyterLab / Jupyter Notebook | C7: 4.0+ | D7: Yes | E7: conda install -c conda-forge jupyterlab | F7: Primary interactive development environment for all labs | G7: jupyter lab --version
A8: 4 | B8: Visual Studio Code | C8: Latest | D8: Yes | E8: Download from code.visualstudio.com and install the Python and Jupyter extensions | F8: Script development, packaging, debugging and testing | G8: code --version
A9: 5 | B9: NumPy | C9: 1.26+ | D9: Yes | E9: pip install numpy | F9: Numerical computing and array operations (Module 3) | G9: import numpy; numpy.__version__
A10: 6 | B10: Pandas | C10: 2.1+ | D10: Yes | E10: pip install pandas | F10: Data analysis, wrangling and aggregation (Modules 4-5) | G10: import pandas; pandas.__version__
A11: 7 | B11: Matplotlib | C11: 3.8+ | D11: Yes | E11: pip install matplotlib | F11: Core plotting and figure control (Module 6) | G11: import matplotlib
A12: 8 | B12: Seaborn | C12: 0.13+ | D12: Yes | E12: pip install seaborn | F12: Statistical visualisation and faceting (Module 6) | G12: import seaborn
A13: 9 | B13: scikit-learn | C13: 1.4+ | D13: Yes | E13: pip install scikit-learn | F13: Machine learning algorithms, pipelines and metrics (Modules 7-10) | G13: import sklearn; sklearn.__version__
A14: 10 | B14: SciPy | C14: 1.11+ | D14: Yes | E14: pip install scipy | F14: Statistical tests and scientific computing (Module 7) | G14: import scipy
A15: 11 | B15: statsmodels | C15: 0.14+ | D15: Yes | E15: pip install statsmodels | F15: Regression diagnostics, VIF and statistical summaries | G15: import statsmodels
A16: 12 | B16: openpyxl | C16: 3.1+ | D16: Yes | E16: pip install openpyxl | F16: Reading and writing Excel files with Pandas | G16: import openpyxl
... A26: 22 | B26: Git | C26: 2.4+ | D26: Recommended | E26: Download from git-scm.com | F26: Version control for the capstone repository (Module 10) | G26: git --version
A28: ONE-LINE SETUP (recommended): conda create -n pyds python=3.11 -y && conda activate pyds && pip install -r requirements.txt
A29: Hardware minimum: 8 GB RAM (16 GB recommended), 20 GB free disk, dual-core processor or better.
A30: Corporate laptops: confirm administrator rights and proxy or firewall exceptions for pypi.org, anaconda.org, files.pythonhosted.org and github.com at least 3 working days before Day 1.
A31: Cloud fallback if local installation is blocked: Google Colab (colab.research.google.com) or Kaggle Notebooks - both come with the full stack pre-installed and require only a browser.
A32: A pre-training setup validation session is recommended 1-2 days before Day 1 so no classroom time is lost to installation issues.
A33: PERSONAL ACCOUNTS AND TOOLING: No company software, licences or accounts will be provided. Every participant installs the stack on their own machine and uses a personal GitHub account for assignment submission. No organisation access, CI service or advanced permissions are required.
A34: NO EMPLOYER CODE OR DATA: Labs, home assignments and the capstone use public datasets or the sample data supplied in class. No employer source code or confidential data should be placed in a personal repository.

Sheet Datasets & Resources
A1: DATASETS & LEARNING RESOURCES
A2: Datasets used in the labs, plus curated post-training learning resources
A4: SECTION A - DATASETS USED IN LABS
A5: S.No | B5: Dataset Name | C5: Used In Module | D5: Approx. Size | E5: Source / How to Obtain | F5: Why This Dataset
A6: 1 | B6: Telco Customer Churn | C6: Modules 4, 5, 6, 8, 10 | D6: 7,043 rows x 21 cols | E6: Kaggle - 'Telco Customer Churn' (IBM sample dataset); CSV mirrored in the course pack | F6: Mixed numeric and categorical columns, real missing values and mild class imbalance - the reference dataset for the whole program
A7: 2 | B7: IBM HR Employee Attrition | C7: Modules 5, 8, 10 (alternate capstone) | D7: 1,470 rows x 35 cols | E7: Kaggle - 'IBM HR Analytics Employee Attrition & Performance' | F7: Rich categorical features and a clear business narrative for attrition-driver analysis
A8: 3 | B8: Ames / Boston-style Housing | C8: Modules 3, 8.2, 8.3 | D8: 1,460 rows x 81 cols | E8: Kaggle - 'House Prices: Advanced Regression Techniques' | F8: The reference regression dataset - many features, skewed target and heavy missingness
A9: 4 | B9: Loan Approval / Credit Risk | C9: Modules 8.4, 10 (alternate capstone) | D9: ~600-10,000 rows | E9: Kaggle - 'Loan Prediction Problem' or 'Give Me Some Credit' | F9: Classification with real business cost asymmetry between false positives and false negatives
A10: 5 | B10: Retail / E-commerce Transactions | C10: Modules 4.5, 4.6, 4.8, 9.1 | D10: ~540,000 rows | E10: UCI Machine Learning Repository - 'Online Retail' | F10: Volume, joins, time series and RFM feature engineering for segmentation
A11: 6 | B11: Application Log Sample | C11: Modules 1.4, 2.1, 2.2, 2.6 | D11: ~50,000 lines | E11: Provided in the course pack (synthetic, anonymised) | F11: Domain-relevant text parsing for QA, SDET and support participants
A12: 7 | B12: Test Execution Results | C12: Modules 1.3, 1.6, 2.2 | D12: ~5,000 rows | E12: Provided in the course pack (synthetic) | F12: Automation-metrics data that mirrors the participants' own day-to-day work
A13: 8 | B13: Iris / Wine / Digits (built-in) | C13: Modules 7, 8.8, 9.3 | D13: 150-1,797 rows | E13: sklearn.datasets.load_iris(), load_wine(), load_digits() | F13: Instant, dependency-free datasets for demonstrating concepts without ingestion overhead
A14: 9 | B14: Synthetic datasets | C14: Modules 7.6, 9.1, 9.2 | D14: Configurable | E14: sklearn.datasets.make_classification(), make_regression(), make_blobs() | F14: Controlled data for demonstrating overfitting, cluster shape and algorithm behaviour
A16: SECTION B - POST-TRAINING LEARNING RESOURCES
A17: S.No | B17: Resource | C17: Type | D17: Level | E17: Where to Find It | F17: Recommended For
A18: 1 | B18: Official Python Tutorial | C18: Documentation | D18: Beginner | E18: docs.python.org/3/tutorial | F18: Reinforcing Module 1 and 2 fundamentals
A19: 2 | B19: NumPy User Guide | C19: Documentation | D19: Beginner | E19: numpy.org/doc/stable/user | F19: Deepening Module 3 array and broadcasting skills
A20: 3 | B20: Pandas User Guide & Cookbook | C20: Documentation | D20: Intermediate | E20: pandas.pydata.org/docs/user_guide | F20: The single most valuable reference after this program
A21: 4 | B21: scikit-learn User Guide | C21: Documentation | D21: Intermediate | E21: scikit-learn.org/stable/user_guide.html | F21: Algorithm theory, parameters and worked examples for Modules 7-9
A22: 5 | B22: Python for Data Analysis (Wes McKinney) | C22: Book | D22: Beginner-Intermediate | E22: O'Reilly | F22: The definitive Pandas book, written by its creator
A23: 6 | B23: Hands-On Machine Learning (Aurelien Geron) | C23: Book | D23: Intermediate | E23: O'Reilly | F23: The best practical follow-up to Modules 7-10
A24: 7 | B24: An Introduction to Statistical Learning (ISLP) | C24: Book (free PDF) | D24: Intermediate-Advanced | E24: statlearning.com | F24: The statistical theory behind every algorithm taught here
A25: 8 | B25: Kaggle Learn micro-courses | C25: Interactive course | D25: Beginner-Intermediate | E25: kaggle.com/learn | F25: Short, hands-on modules on Pandas, feature engineering and ML
A26: 9 | B26: Kaggle Competitions (Getting Started) | C26: Practice | D26: Intermediate | E26: kaggle.com/competitions | F26: Applying the capstone workflow to new problems with a leaderboard
A27: 10 | B27: StatQuest with Josh Starmer | C27: Video channel | D27: Beginner | E27: YouTube | F27: Clear visual intuition for every ML and statistics concept in Module 7
A28: 11 | B28: MLOps Zoomcamp / Made With ML | C28: Course | D28: Advanced | E28: github.com/DataTalksClub, madewithml.com | F28: The natural next step after Module 9 deployment topics
A29: 12 | B29: Papers with Code | C29: Reference | D29: Advanced | E29: paperswithcode.com | F29: Tracking state-of-the-art methods once the fundamentals are solid
A31: Note: All Kaggle and UCI datasets are downloaded once and shipped in the offline course pack so that labs are not dependent on internet access or account creation during the session.

Sheet Capstone Project Details
A1: CAPSTONE PROJECT - CUSTOMER CHURN PREDICTION (ENTERPRISE SIMULATION)
A2: Module 10 | 270 Minutes | Alternates: Employee Attrition, House Price, Loan Approval
A4: SECTION A - PROJECT BRIEF
A5: Project Title | C5: Customer Churn Prediction & Retention Intelligence
A6: Business Context | C6: A subscription telecom provider is losing approximately 26% of its customer base annually. Retention campaigns are currently sprayed across the entire base at high cost and low conversion.
A7: Business Problem | C7: Identify, in advance, which customers are likely to churn in the next billing cycle, and explain why, so that retention spend can be targeted at the customers who are both at risk and worth saving.
A8: ML Problem Statement | C8: Binary classification: predict P(churn = Yes) for each active customer at the end of a monthly observation window.
A9: Target Variable | C9: Churn (Yes / No) - approximately 26% positive class
A10: Prediction Window | C10: Next 1 billing cycle (30 days)
A11: Primary Metric | C11: Recall on the churn class at a fixed precision floor, with ROC-AUC as the ranking metric
A12: Why Not Accuracy | C12: A model predicting 'no churn' for everyone scores 74% accuracy and delivers zero business value - accuracy is explicitly rejected as the decision metric
A13: Baseline to Beat | C13: Current rule-based targeting: contract type = month-to-month AND tenure < 12 months
A14: Business Success Criteria | C14: Capture at least 70% of actual churners within the top 3 deciles of predicted risk, with a documented estimated revenue saving
A15: Dataset | C15: Telco Customer Churn - 7,043 customers x 21 attributes (demographics, account, services, billing)
A16: Constraints | C16: Model must be explainable at the individual-customer level; scoring must run as a monthly batch; no protected demographic attribute may drive the decision
A17: Alternate Projects | C17: Employee Attrition Prediction (HR) | House Price Prediction (regression variant) | Loan Approval Prediction (credit risk)
A19: SECTION B - EXECUTION PHASES
A20: Phase | B20: Phase Name | C20: Activities | D20: Techniques / Libraries | E20: Duration (Min) | F20: Deliverable
A21: P1 | B21: Business Problem Framing | C21: Restate the objective; define the target and observation window; agree the success metric and baseline; document scope, assumptions and constraints; set up repository and environment | D21: Project charter template, Git, conda | E21: 25 | F21: Project charter + initialised repo
A22: P2 | B22: Data Collection & Ingestion | C22: Identify sources; review schema and data dictionary; ingest raw files; validate row counts and dtypes; reconcile against source; freeze an immutable raw layer | D22: Pandas read_csv / read_excel / read_sql | E22: 25 | F22: Raw data layer + data dictionary
A23: P3 | B23: Data Cleaning & Quality | C23: Profile quality; treat missing TotalCharges; remove duplicates; treat outliers; standardise categories and types; log every transformation | D23: Pandas, NumPy, SimpleImputer, IQR method | E23: 30 | F23: Cleaned dataset + transformation log
A24: P4 | B24: Exploratory Data Analysis | C24: Univariate, bivariate and multivariate analysis against churn; churn rate by contract, tenure band, payment method and services; correlation analysis; quantify every observation | D24: Matplotlib, Seaborn, Pandas groupby, crosstab | E24: 35 | F24: EDA notebook + 10 quantified insights
A25: P5 | B25: Feature Engineering & Selection | C25: Tenure bands; average charge per month; service-count feature; contract and payment encoding; interaction features; scaling; RFE and correlation filtering; leakage review | D25: Pandas, OneHotEncoder, StandardScaler, RFE | E25: 30 | F25: Feature specification + modelling dataset
A26: P6 | B26: Model Building | C26: Train the baseline; train Logistic Regression, Decision Tree, Random Forest and XGBoost inside pipelines; handle class imbalance with class weights and SMOTE; log every experiment | D26: scikit-learn Pipeline, XGBoost, imbalanced-learn | E26: 40 | F26: Candidate models + experiment log
A27: P7 | B27: Evaluation, Tuning & Selection | C27: Cross-validated comparison; GridSearchCV / RandomizedSearchCV on the shortlist; confusion matrix, ROC-AUC and PR curves; threshold optimisation against a cost matrix; final selection with justification | D27: GridSearchCV, StratifiedKFold, sklearn.metrics | E27: 35 | F27: Final tuned model + evaluation report
A28: P8 | B28: Prediction & Business Insights | C28: Score the holdout set; build risk deciles; identify the top churn drivers with feature importance and SHAP; size the addressable at-risk revenue; write recommendations and a monitoring plan | D28: SHAP, Pandas, Matplotlib | E28: 30 | F28: Scored output + business impact analysis
A29: P9 | B29: Presentation & Walkthrough | C29: Present the executive narrative and the technical walkthrough; defend three design decisions; capture limitations and next steps; draft an individual 90-day learning roadmap | D29: Jupyter, PowerPoint | E29: 20 | F29: Capstone deck + final repository
D30: TOTAL CAPSTONE DURATION | E30: =SUM(E21:E29) | F30: =ROUND(E30/60,1)&" hours"
A32: SECTION C - EVALUATION RUBRIC
A33: S.No | B33: Criterion | C33: What Is Assessed | D33: Weight (%)
A34: 1 | B34: Problem Framing & Approach | C34: Clarity of the problem statement, target definition, metric choice and baseline; quality of assumptions | D34: 10
A35: 2 | B35: Data Cleaning & Quality | C35: Correctness and justification of missing-value, outlier and consistency treatment; completeness of the transformation log | D35: 15
A36: 3 | B36: EDA & Insight Quality | C36: Depth of exploration, chart appropriateness, and whether insights are quantified and business-relevant | D36: 15
A37: 4 | B37: Feature Engineering | C37: Creativity and domain relevance of engineered features; soundness of selection; leakage review | D37: 15
A38: 5 | B38: Modelling & Evaluation | C38: Breadth of candidates, validation rigour, metric appropriateness, tuning and threshold logic | D38: 20
A39: 6 | B39: Code Quality & Reproducibility | C39: Structure, readability, PEP 8 adherence, pipeline usage, seeds, and whether the notebook runs end to end | D39: 10
A40: 7 | B40: Business Communication | C40: Quality of the recommendation, impact quantification, and clarity of the presentation to a non-technical audience | D40: 15
C41: TOTAL | D41: =SUM(D34:D40)
A43: SECTION D - FINAL SUBMISSION CHECKLIST
A44: 1. | B44: Cleaned dataset and a documented transformation log
...

Sheet Home Assignments
A1: HOME ASSIGNMENTS — PYTHON FOR DATA SCIENCE & MACHINE LEARNING (40 HRS)
A2: Four graded home assignments | 17-21 hours total | Completed on personal machines and personal GitHub accounts between training days
A4: Assignment | B4: Title | C4: Assigned After | D4: Due Before | E4: Effort (Hrs) | F4: Focus | G4: Task | H4: Requirements | I4: Expected Outcomes | J4: Submission Format
A5: HA-1 | B5: Reusable Python Utility Package | C5: End of Day 2 | D5: Start of Day 4 | E5: 3-4 | F5: Consolidating core and advanced Python — functions, collections, comprehensions, OOP, exceptions, file handling and packaging — into something reusable rather than throwaway notebook code. | G5: Build a small installable Python package of data-cleaning and validation utilities: functions to trim and standardise text, coerce and validate numeric and date fields, detect and report malformed rows, and read and write CSV and JSON safely. Structure it as a proper package with modules, not a single script. Include a Dataset class that wraps a file and exposes shape and summary properties. | H5: Personal GitHub repository created on your own account. Package must include __init__.py, a requirements.txt and a README. Every public function must carry a docstring and type hints. Use comprehensions and generator expressions where they genuinely improve the code. Custom exception classes and structured logging for the failure paths. A minimum of three pytest cases covering a happy path, an edge case and a failure. Code must be PEP 8 compliant. | I5: An installable package that can be imported from a clean notebook. A passing pytest suite. Demonstrated understanding of when a comprehension helps and when it hurts readability. A reusable asset you will actually use in the later assignments and the capstone. | J5: GitHub repository link + passing test output
A6: HA-2 | B6: NumPy & Pandas Multi-Source Analysis | C6: End of Day 4 | D6: Start of Day 5 | E6: 4-5 | F6: Vectorised numerical computing and real multi-source data analysis — the daily working skill of the whole programme. | G6: Take a public dataset of your choice with at least two related tables (or split one into related tables) and produce a complete analysis notebook. Ingest from CSV and Excel, clean and type the columns, join the tables into a single analysis table, aggregate with GroupBy, reshape with a pivot, and add a time-based aggregation with resample and a rolling window. Use NumPy for at least one vectorised computation and benchmark it against the equivalent loop. | H6: Notebook must run top to bottom without error on a fresh kernel. Every join must be validated with a row-count reconciliation before and after, and any row explosion explained. No row-wise apply where a vectorised operation exists — justify any exception. The NumPy benchmark must report measured timings, not estimates. Minimum eight quantified business insights, each stated as a number with the code that produced it. | I6: An analysis notebook that another participant can run unchanged. A written insight summary with eight quantified findings. Demonstrated fluency in selection, GroupBy, merge, pivot and time-series operations. Evidence that you can reason about the performance cost of a Pandas operation. | J6: Jupyter notebook + insight summary
A7: HA-3 | B7: EDA, Data Quality & Feature Engineering Report | C7: End of Day 6 | D7: Start of Day 8 | E7: 5-6 | F7: Turning a raw dataset into a clean, leakage-free modelling dataset, and communicating what the data is telling you. | G7: Using the capstone dataset (Telco churn, or an approved alternative), run a complete exploratory analysis and prepare the modelling dataset. Profile the data and produce a quality scorecard. Treat missing values, duplicates and outliers. Encode categoricals and scale numerics appropriately for the algorithms you intend to use. Engineer new features from the domain. Then produce the EDA report with visualisations and quantified insights. | H7: Every cleaning and encoding decision must be justified in writing — a comparison of at least two strategies is required for missing values. A before-and-after data quality scorecard. At least eight engineered features, each with a written definition and rationale. A leakage review confirming no feature encodes future information and that all transformers were fitted on training data only. Minimum ten quantified insights, each with an annotated supporting chart. Charts must have titles, axis labels and readable scales. | I7: A cleaned, documented modelling dataset with a transformation log. An EDA report notebook containing ten quantified business insights with supporting visuals. A feature specification document. A completed leakage review. This becomes the direct input to your capstone. | J7: EDA notebook + feature specification + transformation log
A8: HA-4 | B8: Model Build, Tuning, Explainability & Scoring Service | C8: End of Day 9 | D8: Start of Day 10 | E8: 5-6 | F8: The full modelling workflow — baseline, candidates, tuning, threshold selection, explainability and deployment — assembled into one leakage-free artefact. | G8: Using the dataset from HA-3, establish a baseline model, then train at least four candidate algorithms across families inside scikit-learn Pipelines. Tune the top two with GridSearchCV or RandomizedSearchCV. Choose the decision metric on business grounds and tune the classification threshold against a cost matrix. Produce a SHAP driver analysis, explain one individual prediction end to end, then serialise the complete pipeline and expose a local /predict endpoint. | H8: Every model must be trained inside a Pipeline with ColumnTransformer — no preprocessing fitted outside the pipeline. An experiment log recording every model, its parameters and its cross-validated scores. Metric choice must be justified in business terms, and accuracy explicitly rejected as the decision metric with a reason. Threshold selection must reference a stated cost of false positives versus false negatives. The saved artefact must contain preprocessing and model together. The endpoint must accept a raw record and return a scored response. | I8: A model leaderboard comparing all candidates on a common protocol, with a written selection recommendation. A tuned, serialised pipeline artefact. A running local /predict endpoint with sample requests and responses. A SHAP-based driver analysis and one fully explained individual prediction. A short model card covering intended use, limitations and monitoring. Capstone-ready on Day 10. | J8: Model leaderboard + pipeline artefact + running endpoint + model card
D9: TOTAL EFFORT | E9: 17-21 hrs
A11: PERSONAL ACCOUNTS AND TOOLING: All home assignments are completed on the participant's own personal GitHub account and personally installed tooling. No company software, licences, accounts or repositories are provided or required.
A12: NO EMPLOYER CODE OR DATA: Assignments must use public datasets, personally created sample data, or the sample domain supplied in class. Do not commit employer source code, customer data or any confidential material to a personal repository.
A13: EFFORT GUIDANCE: Each assignment is sized at 3-6 hours of independent work, designed to fit between two consecutive training days. Assignments build on one another — the output of one becomes the input of the next, and all four feed directly into the Day 10 capstone.
A14: SUBMISSION: Share the repository link by the stated due date. Assignments are reviewed at the start of the following session, with two selected for group walkthrough.
A15: ASSESSMENT: Home assignments carry weight in the final certification. A participant who has not completed HA-1 to HA-4 will not have the codebase or the plan required to complete the capstone within the scheduled time.
